<?xml version="1.0" encoding="utf-8"?>
<!-- This URDF was automatically created by SolidWorks to URDF Exporter! Originally created by Stephen Brawner (brawner@gmail.com)
     Commit Version: 1.5.1-0-g916b5db  Build Version: 1.5.7152.31018
     For more information, please see http://wiki.ros.org/sw_urdf_exporter -->
<robot
  name="cheeta_pkg_v4">
  <link
    name="base_link">
    <inertial>
      <origin
        xyz="-0.0030602 0.000606 -0.0024102"
        rpy="0 0 0" />
      <mass
        value="0.80181" />
      <inertia
        ixx="0.0017391"
        ixy="-7.1351E-19"
        ixz="7.8351E-20"
        iyy="0.0011723"
        iyz="8.3765E-06"
        izz="0.0017256" />
    </inertial>
    <visual>
      <origin
        xyz="0 0 0"
        rpy="0 0 0" />
      <geometry>
        <mesh
          filename="package://cheeta_pkg_v4/meshes/base_link.STL" />
      </geometry>
      <material
        name="">
        <color
          rgba="0.75294 0.75294 0.75294 1" />
      </material>
    </visual>
    <collision>
      <origin
        xyz="0 0 0"
        rpy="0 0 0" />
      <geometry>
        <mesh
          filename="package://cheeta_pkg_v4/meshes/base_link.STL" />
      </geometry>
    </collision>
  </link>
  <link
    name="abductor1_link">
    <inertial>
      <origin
        xyz="-0.011184 -0.008665 -0.028915"
        rpy="0 0 0" />
      <mass
        value="0.087801" />
      <inertia
        ixx="2.3479E-05"
        ixy="2.2102E-06"
        ixz="4.9491E-07"
        iyy="4.0046E-05"
        iyz="2.609E-06"
        izz="3.3238E-05" />
    </inertial>
    <visual>
      <origin
        xyz="0 0 0"
        rpy="0 0 0" />
      <geometry>
        <mesh
          filename="package://cheeta_pkg_v4/meshes/abductor1_link.STL" />
      </geometry>
      <material
        name="">
        <color
          rgba="0.75294 0.75294 0.75294 1" />
      </material>
    </visual>
    <collision>
      <origin
        xyz="0 0 0"
        rpy="0 0 0" />
      <geometry>
        <mesh
          filename="package://cheeta_pkg_v4/meshes/abductor1_link.STL" />
      </geometry>
    </collision>
  </link>
  <joint
    name="abductor1_joint"
    type="revolute">
    <origin
      xyz="0.144939786584407 0.0558284749900594 0.0118733032573917"
      rpy="-1.57145977887313 -1.57079631189374 -1.57079632679467" />
    <parent
      link="base_link" />
    <child
      link="abductor1_link" />
    <axis
      xyz="0 0 1" />
    <limit
      lower="-3.1416"
      upper="3.1416"
      effort="300"
      velocity="15" />
    <dynamics
      damping="0.05"
      friction="0.1" />
  </joint>
  <link
    name="muslo1_link">
    <inertial>
      <origin
        xyz="-0.032741 -0.028029 0.027728"
        rpy="0 0 0" />
      <mass
        value="0.17564" />
      <inertia
        ixx="0.0001594"
        ixy="-9.9344E-05"
        ixz="-6.8942E-06"
        iyy="0.00012193"
        iyz="-6.2762E-06"
        izz="0.00023829" />
    </inertial>
    <visual>
      <origin
        xyz="0 0 0"
        rpy="0 0 0" />
      <geometry>
        <mesh
          filename="package://cheeta_pkg_v4/meshes/muslo1_link.STL" />
      </geometry>
      <material
        name="">
        <color
          rgba="0.75294 0.75294 0.75294 1" />
      </material>
    </visual>
    <collision>
      <origin
        xyz="0 0 0"
        rpy="0 0 0" />
      <geometry>
        <mesh
          filename="package://cheeta_pkg_v4/meshes/muslo1_link.STL" />
      </geometry>
    </collision>
  </link>
  <joint
    name="muslo1_joint"
    type="revolute">
    <origin
      xyz="-0.0108654 -0.030737 -0.028"
      rpy="1.5708 1.57 0" />
    <parent
      link="abductor1_link" />
    <child
      link="muslo1_link" />
    <axis
      xyz="0 0 1" />
    <limit
      lower="-3.1416"
      upper="3.1416"
      effort="300"
      velocity="15" />
    <dynamics
      damping="0.05"
      friction="0.1" />
  </joint>
  <link
    name="tobillo1_link">
    <inertial>
      <origin
        xyz="-0.030588 0.0057261 -0.019121"
        rpy="0 0 0" />
      <mass
        value="0.10067" />
      <inertia
        ixx="1.8616E-05"
        ixy="3.3005E-06"
        ixz="-1.054E-05"
        iyy="8.0339E-05"
        iyz="1.1024E-06"
        izz="7.4714E-05" />
    </inertial>
    <visual>
      <origin
        xyz="0 0 0"
        rpy="0 0 0" />
      <geometry>
        <mesh
          filename="package://cheeta_pkg_v4/meshes/tobillo1_link.STL" />
      </geometry>
      <material
        name="">
        <color
          rgba="0.75294 0.75294 0.75294 1" />
      </material>
    </visual>
    <collision>
      <origin
        xyz="0 0 0"
        rpy="0 0 0" />
      <geometry>
        <mesh
          filename="package://cheeta_pkg_v4/meshes/tobillo1_link.STL" />
      </geometry>
    </collision>
  </link>
  <joint
    name="tobillo1_joint"
    type="revolute">
    <!--- xyz="-0.0127837602404866 0.0950382018322965 0.00845621900238935"
      rpy="0 -0.0151338374432169 0" / -->
    <origin
      xyz="-0.025 -0.0925 0.0081226910564016"
      rpy="0 0 1.570796327" />
    <parent
      link="muslo1_link" />
    <child
      link="tobillo1_link" />
    <axis
      xyz="0 0 1" />
    <limit
      lower="-3.1416"
      upper="3.1416"
      effort="300"
      velocity="15" />
    <dynamics
      damping="0.05"
      friction="0.1" />
  </joint>
  <link
    name="abductor2_link">
    <inertial>
      <origin
        xyz="-0.01296 0.0056756 -0.028915"
        rpy="0 0 0" />
      <mass
        value="0.087801" />
      <inertia
        ixx="2.551E-05"
        ixy="-5.8659E-06"
        ixz="1.1163E-06"
        iyy="3.8015E-05"
        iyz="-2.4095E-06"
        izz="3.3238E-05" />
    </inertial>
    <visual>
      <origin
        xyz="0 0 0"
        rpy="0 0 0" />
      <geometry>
        <mesh
          filename="package://cheeta_pkg_v4/meshes/abductor2_link.STL" />
      </geometry>
      <material
        name="">
        <color
          rgba="0.75294 0.75294 0.75294 1" />
      </material>
    </visual>
    <collision>
      <origin
        xyz="0 0 0"
        rpy="0 0 0" />
      <geometry>
        <mesh
          filename="package://cheeta_pkg_v4/meshes/abductor2_link.STL" />
      </geometry>
    </collision>
  </link>
  <joint
    name="abductor2_joint"
    type="revolute">
    <origin
      xyz="-0.15106 0.055828 0.011873"
      rpy="-1.5708 -1.5557 1.5708" />
    <parent
      link="base_link" />
    <child
      link="abductor2_link" />
    <axis
      xyz="0 0 -1" />
    <limit
      lower="-3.1416"
      upper="3.1416"
      effort="300"
      velocity="15" />
    <dynamics
      damping="0.05"
      friction="0.1" />
  </joint>
  <link
    name="muslo2_link">
    <inertial>
      <origin
        xyz="0.026044 0.037079 0.023943"
        rpy="0 0 0" />
      <mass
        value="0.17563" />
      <inertia
        ixx="0.00022671"
        ixy="-5.3779E-05"
        ixz="4.022E-06"
        iyy="5.5523E-05"
        iyz="1.2653E-05"
        izz="0.00023738" />
    </inertial>
    <visual>
      <origin
        xyz="0 0 0"
        rpy="0 0 0" />
      <geometry>
        <mesh
          filename="package://cheeta_pkg_v4/meshes/muslo2_link.STL" />
      </geometry>
      <material
        name="">
        <color
          rgba="0.75294 0.75294 0.75294 1" />
      </material>
    </visual>
    <collision>
      <origin
        xyz="0 0 0"
        rpy="0 0 0" />
      <geometry>
        <mesh
          filename="package://cheeta_pkg_v4/meshes/muslo2_link.STL" />
      </geometry>
    </collision>
  </link>
  <joint
    name="muslo2_joint"
    type="revolute">
    <origin
      xyz="-0.0108819484572151 0.030088845477184 -0.028"
      rpy="1.5707963267949 1.57 -3.14159265358979" />
    <parent
      link="abductor2_link" />
    <child
      link="muslo2_link" />
    <axis
      xyz="0.015133259758379 0  0.999885485667777" />
    <limit
      lower="-3.1416"
      upper="3.1416"
      effort="300"
      velocity="15" />
    <dynamics
      damping="0.05"
      friction="0.1" />
  </joint>
  <link
    name="tobillo2_link">
    <inertial>
      <origin
        xyz="0.050316 0.007602 0.010147"
        rpy="0 0 0" />
      <mass
        value="0.10067" />
      <inertia
        ixx="3.1441E-05"
        ixy="-1.6336E-05"
        ixz="2.0803E-05"
        iyy="7.5156E-05"
        iyz="6.8787E-06"
        izz="6.7072E-05" />
    </inertial>
    <visual>
      <origin
        xyz="0 0 0"
        rpy="0 0 0" />
      <geometry>
        <mesh
          filename="package://cheeta_pkg_v4/meshes/tobillo2_link.STL" />
      </geometry>
      <material
        name="">
        <color
          rgba="0.75294 0.75294 0.75294 1" />
      </material>
    </visual>
    <collision>
      <origin
        xyz="0 0 0"
        rpy="0 0 0" />
      <geometry>
        <mesh
          filename="package://cheeta_pkg_v4/meshes/tobillo2_link.STL" />
      </geometry>
    </collision>
  </link>
  <joint
    name="tobillo2_joint"
    type="revolute">
    <origin
      xyz="0.0258486456049929 0.0925 0.0076"
      rpy="0 0 1.570796327" />
    <parent
      link="muslo2_link" />
    <child
      link="tobillo2_link" />
    <axis
      xyz="0 0 1" />
    <limit
      lower="-3.1416"
      upper="3.1416"
      effort="300"
      velocity="15" />
    <dynamics
      damping="0.05"
      friction="0.1" />
  </joint>
  <link
    name="abductor3_link">
    <inertial>
      <origin
        xyz="-0.0091904 0.010757 -0.028915"
        rpy="0 0 0" />
      <mass
        value="0.087801" />
      <inertia
        ixx="2.3283E-05"
        ixy="1.2687E-06"
        ixz="-4.5562E-08"
        iyy="4.0242E-05"
        iyz="-2.6551E-06"
        izz="3.3238E-05" />
    </inertial>
    <visual>
      <origin
        xyz="0 0 0"
        rpy="0 0 0" />
      <geometry>
        <mesh
          filename="package://cheeta_pkg_v4/meshes/abductor3_link.STL" />
      </geometry>
      <material
        name="">
        <color
          rgba="0.75294 0.75294 0.75294 1" />
      </material>
    </visual>
    <collision>
      <origin
        xyz="0 0 0"
        rpy="0 0 0" />
      <geometry>
        <mesh
          filename="package://cheeta_pkg_v4/meshes/abductor3_link.STL" />
      </geometry>
    </collision>
  </link>
  <joint
    name="abductor3_joint"
    type="revolute">
    <origin
      xyz="0.14494 -0.054159 0.013538"
      rpy="-1.5708 -1.5708 -1.5708" />
    <parent
      link="base_link" />
    <child
      link="abductor3_link" />
    <axis
      xyz="0 0 1" />
    <limit
      lower="-3.1416"
      upper="3.1416"
      effort="300"
      velocity="15" />
    <dynamics
      damping="0.05"
      friction="0.1" />
  </joint>
  <link
    name="muslo3_link">
    <inertial>
      <origin
        xyz="0.00695144352453009 -0.0390164148800795 0.0324930436073015"
        rpy="0 0 0" />
      <mass
        value="0.175633361338535" />
      <inertia
        ixx="0.000238164844520679"
        ixy="2.46651107780594E-05"
        ixz="4.98189550567534E-07"
        iyy="4.27042124006498E-05"
        iyz="1.01072737475027E-05"
        izz="0.000238744604178462" />
    </inertial>
    <visual>
      <origin
        xyz="0 0 0"
        rpy="0 0 0" />
      <geometry>
        <mesh
          filename="package://cheeta_pkg_v4/meshes/muslo3_link.STL" />
      </geometry>
      <material
        name="">
        <color
          rgba="0.752941176470588 0.752941176470588 0.752941176470588 1" />
      </material>
    </visual>
    <collision>
      <origin
        xyz="0 0 0"
        rpy="0 0 0" />
      <geometry>
        <mesh
          filename="package://cheeta_pkg_v4/meshes/muslo3_link.STL" />
      </geometry>
    </collision>
  </link>
  <joint
    name="muslo3_joint"
    type="revolute">
    <origin
      xyz="-0.01000789906171363 0.0307009998324582 -0.0280000000000002"
      rpy="1.5707963267949 -1.57 3.14159265358979" />
    <parent
      link="abductor3_link" />
    <child
      link="muslo3_link" />
    <axis
      xyz="0 0 1" />
    <limit
      lower="-3.1416"
      upper="3.1416"
      effort="300"
      velocity="15" />
    <dynamics
      damping="0.05"
      friction="0.1" />
  </joint>
  <link
    name="tobillo3_link">
    <inertial>
      <origin
        xyz="0.040525 -0.0093071 0.031041"
        rpy="0 0 0" />
      <mass
        value="0.10067" />
      <inertia
        ixx="2.3383E-05"
        ixy="1.9768E-05"
        ixz="-9.9044E-07"
        iyy="7.3657E-05"
        iyz="9.649E-07"
        izz="7.6629E-05" />
    </inertial>
    <visual>
      <origin
        xyz="0 0 0"
        rpy="0 0 0" />
      <geometry>
        <mesh
          filename="package://cheeta_pkg_v4/meshes/tobillo3_link.STL" />
      </geometry>
      <material
        name="">
        <color
          rgba="0.75294 0.75294 0.75294 1" />
      </material>
    </visual>
    <collision>
      <origin
        xyz="0 0 0"
        rpy="0 0 0" />
      <geometry>
        <mesh
          filename="package://cheeta_pkg_v4/meshes/tobillo3_link.STL" />
      </geometry>
    </collision>
  </link>
  <joint
    name="tobillo3_joint"
    type="revolute">

    <origin
      xyz="0.0257675325458557 -0.0915293601607581 0.0108872557651566"
      rpy="0 0 -1.27" />
    <parent
      link="muslo3_link" />
    <child
      link="tobillo3_link" />
    <axis
      xyz="0 0 1" />
    <limit
      lower="-3.1416"
      upper="3.1416"
      effort="300"
      velocity="15" />
    <dynamics
      damping="0.05"
      friction="0.1" />
  </joint>
  <link
    name="abductor4_link">
    <inertial>
      <origin
        xyz="-0.010171 -0.0098349 -0.028915"
        rpy="0 0 0" />
      <mass
        value="0.087801" />
      <inertia
        ixx="2.3196E-05"
        ixy="3.5838E-07"
        ixz="2.0694E-07"
        iyy="4.0329E-05"
        iyz="2.6474E-06"
        izz="3.3238E-05" />
    </inertial>
    <visual>
      <origin
        xyz="0 0 0"
        rpy="0 0 0" />
      <geometry>
        <mesh
          filename="package://cheeta_pkg_v4/meshes/abductor4_link.STL" />
      </geometry>
      <material
        name="">
        <color
          rgba="0.75294 0.75294 0.75294 1" />
      </material>
    </visual>
    <collision>
      <origin
        xyz="0 0 0"
        rpy="0 0 0" />
      <geometry>
        <mesh
          filename="package://cheeta_pkg_v4/meshes/abductor4_link.STL" />
      </geometry>
    </collision>
  </link>
  <joint
    name="abductor4_joint"
    type="revolute">
    <origin
      xyz=" -0.151060213415592 -0.0541589284333917 0.0135379618308107"
      rpy="-1.57013287471666 -1.57079631189374 1.57079632679467" />
    <parent
      link="base_link" />
    <child
      link="abductor4_link" />
    <axis
      xyz="0 0 -1" />
    <limit
      lower="-3.1416"
      upper="3.1416"
      effort="300"
      velocity="15" />
    <dynamics
      damping="0.05"
      friction="0.1" />
  </joint>
  <link
    name="muslo4_link">
    <inertial>
      <origin
        xyz="-0.0037038 0.039999 0.031823"
        rpy="0 0 0" />
      <mass
        value="0.17563" />
      <inertia
        ixx="0.00024121"
        ixy="-8.6827E-06"
        ixz="-1.853E-06"
        iyy="3.9893E-05"
        iyz="-8.5982E-06"
        izz="0.00023851" />
    </inertial>
    <visual>
      <origin
        xyz="0 0 0"
        rpy="0 0 0" />
      <geometry>
        <mesh
          filename="package://cheeta_pkg_v4/meshes/muslo4_link.STL" />
      </geometry>
      <material
        name="">
        <color
          rgba="0.75294 0.75294 0.75294 1" />
      </material>
    </visual>
    <collision>
      <origin
        xyz="0 0 0"
        rpy="0 0 0" />
      <geometry>
        <mesh
          filename="package://cheeta_pkg_v4/meshes/muslo4_link.STL" />
      </geometry>
    </collision>
  </link>
  <joint
    name="muslo4_joint"
    type="revolute">
    <origin
      xyz="-0.0108649683023063 -0.0307075310598279 -0.0279999999999936"
      rpy="1.5707963267947 -1.57 0.0151338374432169" />
    <parent
      link="abductor4_link" />
    <child
      link="muslo4_link" />
    <axis
      xyz="0 0 1" />
    <limit
      lower="-3.1416"
      upper="3.1416"
      effort="300"
      velocity="15" />
    <dynamics
      damping="0.05"
      friction="0.1" />
  </joint>
  <link
    name="tobillo4_link">
    <inertial>
      <origin
        xyz="-0.041723 0.014752 0.027093"
        rpy="0 0 0" />
      <mass
        value="0.10067" />
      <inertia
        ixx="2.9613E-05"
        ixy="2.5553E-05"
        ixz="-3.8286E-06"
        iyy="6.7711E-05"
        iyz="1.4126E-06"
        izz="7.6344E-05" />
    </inertial>
    <visual>
      <origin
        xyz="0 0 0"
        rpy="0 0 0" />
      <geometry>
        <mesh
          filename="package://cheeta_pkg_v4/meshes/tobillo4_link.STL" />
      </geometry>
      <material
        name="">
        <color
          rgba="0.75294 0.75294 0.75294 1" />
      </material>
    </visual>
    <collision>
      <origin
        xyz="0 0 0"
        rpy="0 0 0" />
      <geometry>
        <mesh
          filename="package://cheeta_pkg_v4/meshes/tobillo4_link.STL" />
      </geometry>
    </collision>
  </link>
  <joint
    name="tobillo4_joint"
    type="revolute">

    <origin
      xyz="-0.025 0.0940382018322965 0.00845621900238935"
      rpy="0 -0.0151338374432169 -1.27" />
    <parent
      link="muslo4_link" />
    <child
      link="tobillo4_link" />
    <axis
      xyz="0.015133259758377 0 0.999885485667776" />
    <limit
      lower="-3.1416"
      upper="3.1416"
      effort="300"
      velocity="15" />
    <dynamics
      damping="0.05"
      friction="0.1" />
  </joint>
</robot>
